<?xml version="1.0" ?>
<sdf version="1.5">
  <model name="pioneer2dx">
    <link name="chassis">
      <pose>0 0 0.16 0 0 0</pose>
      <inertial>
        <mass>5.67</mass>
        <inertia>
          <ixx>0.07</ixx>
          <iyy>0.08</iyy>
          <izz>0.10</izz>
          <ixy>0</ixy>
          <ixz>0</ixz>
          <iyz>0</iyz>
        </inertia>
      </inertial>
      <collision name="collision">
        <geometry>
          <box>
            <size>0.445 0.277 0.17</size>
          </box>
        </geometry>
      </collision>
      <collision name="castor_collision">
        <pose>-0.200 0 -0.12 0 0 0</pose>
        <geometry>
          <sphere>
            <radius>0.04</radius>
          </sphere>
        </geometry>
        <surface>
          <friction>
            <ode>
              <mu>0</mu>
              <mu2>0</mu2>
              <slip1>1.0</slip1>
              <slip2>1.0</slip2>
            </ode>
          </friction>
        </surface>
      </collision>
      <!-- 简化的视觉元素 - 使用基本几何体代替mesh -->
      <visual name="visual">
        <pose>0 0 0 0 0 0</pose>
        <geometry>
          <box>
            <size>0.445 0.277 0.17</size>
          </box>
        </geometry>
        <material>
          <ambient>0.5 0.5 0.5 1</ambient>
          <diffuse>0.7 0.7 0.7 1</diffuse>
          <specular>0.1 0.1 0.1 1</specular>
        </material>
      </visual>
      <visual name="castor_visual">
        <pose>-0.200 0 -0.12 0 0 0</pose>
        <geometry>
          <sphere>
            <radius>0.04</radius>
          </sphere>
        </geometry>
        <material>
          <ambient>0.2 0.2 0.2 1</ambient>
          <diffuse>0.3 0.3 0.3 1</diffuse>
          <specular>0.1 0.1 0.1 1</specular>
        </material>
      </visual>
    </link>
    
    <link name="right_wheel">
      <pose>0.1 -.17 0.11 0 1.5707 1.5707</pose>
      <inertial>
        <mass>1.5</mass>
        <inertia>
          <ixx>0.0051</ixx>
          <iyy>0.0051</iyy>
          <izz>0.0090</izz>
          <ixy>0</ixy>
          <ixz>0</ixz>
          <iyz>0</iyz>
        </inertia>
      </inertial>
      <collision name="collision">
        <geometry>
          <cylinder>
            <radius>0.11</radius>
            <length>0.05</length>
          </cylinder>
        </geometry>
        <surface>
          <friction>
            <ode>
              <mu>100000.0</mu>
              <mu2>100000.0</mu2>
              <slip1>0.0</slip1>
              <slip2>0.0</slip2>
            </ode>
          </friction>
        </surface>
      </collision>
      <visual name="visual">
        <geometry>
          <cylinder>
            <radius>0.11</radius>
            <length>0.05</length>
          </cylinder>
        </geometry>
        <material>
          <ambient>0.2 0.2 0.2 1</ambient>
          <diffuse>0.3 0.3 0.3 1</diffuse>
          <specular>0.1 0.1 0.1 1</specular>
        </material>
      </visual>
    </link>
    
    <link name="left_wheel">
      <pose>0.1 .17 0.11 0 1.5707 1.5707</pose>
      <inertial>
        <mass>1.5</mass>
        <inertia>
          <ixx>0.0051</ixx>
          <iyy>0.0051</iyy>
          <izz>0.0090</izz>
          <ixy>0</ixy>
          <ixz>0</ixz>
          <iyz>0</iyz>
        </inertia>
      </inertial>
      <collision name="collision">
        <geometry>
          <cylinder>
            <radius>0.11</radius>
            <length>0.05</length>
          </cylinder>
        </geometry>
        <surface>
          <friction>
            <ode>
              <mu>100000.0</mu>
              <mu2>100000.0</mu2>
              <slip1>0.0</slip1>
              <slip2>0.0</slip2>
            </ode>
          </friction>
        </surface>
      </collision>
      <visual name="visual">
        <geometry>
          <cylinder>
            <radius>0.11</radius>
            <length>0.05</length>
          </cylinder>
        </geometry>
        <material>
          <ambient>0.2 0.2 0.2 1</ambient>
          <diffuse>0.3 0.3 0.3 1</diffuse>
          <specular>0.1 0.1 0.1 1</specular>
        </material>
      </visual>
    </link>

    <!-- 3D激光雷达链接 -->
    <link name="lidar_link">
      <pose>0.18 0 0.3 0 0 0</pose>
      <inertial>
        <mass>0.1</mass>
        <inertia>
          <ixx>0.000166667</ixx>
          <iyy>0.000166667</iyy>
          <izz>0.000166667</izz>
          <ixy>0</ixy>
          <ixz>0</ixz>
          <iyz>0</iyz>
        </inertia>
      </inertial>
      <collision name="collision">
        <geometry>
          <cylinder>
            <radius>0.05</radius>
            <length>0.1</length>
          </cylinder>
        </geometry>
      </collision>
      <visual name="visual">
        <geometry>
          <cylinder>
            <radius>0.05</radius>
            <length>0.1</length>
          </cylinder>
        </geometry>
        <material>
          <ambient>0.1 0.1 0.8 1</ambient>
          <diffuse>0.2 0.2 1.0 1</diffuse>
          <specular>0.8 0.8 0.8 1</specular>
        </material>
      </visual>
      <!-- 3D激光雷达传感器 -->
      <sensor name="lidar" type="ray">
        <pose>0 0 0 0 0 0</pose>
        <update_rate>10</update_rate>
        <visualize>true</visualize>
        <ray>
          <scan>
            <horizontal>
              <samples>360</samples>
              <resolution>1</resolution>
              <min_angle>-3.14159</min_angle>
              <max_angle>3.14159</max_angle>
            </horizontal>
            <vertical>
              <samples>16</samples>
              <resolution>1</resolution>
              <min_angle>-0.523599</min_angle>
              <max_angle>0.523599</max_angle>
            </vertical>
          </scan>
          <range>
            <min>0.1</min>
            <max>30.0</max>
            <resolution>0.01</resolution>
          </range>
          <noise>
            <type>gaussian</type>
            <mean>0.0</mean>
            <stddev>0.01</stddev>
          </noise>
        </ray>
        <plugin name="gazebo_ros_lidar" filename="libgazebo_ros_ray_sensor.so">
          <ros>
            <namespace></namespace>
            <remapping>~/out:=scan</remapping>
          </ros>
          <output_type>sensor_msgs/PointCloud2</output_type>
          <frame_name>chassis</frame_name>
        </plugin>
      </sensor>
    </link>

    <!-- 2D激光雷达链接 -->
    <link name="laser_link">
      <pose>0.18 0 0.27 0 0 0</pose>
      <inertial>
        <mass>0.08</mass>
        <inertia>
          <ixx>0.000133333</ixx>
          <iyy>0.000133333</iyy>
          <izz>0.000133333</izz>
          <ixy>0</ixy>
          <ixz>0</ixz>
          <iyz>0</iyz>
        </inertia>
      </inertial>
      <collision name="collision">
        <geometry>
          <cylinder>
            <radius>0.03</radius>
            <length>0.06</length>
          </cylinder>
        </geometry>
      </collision>
      <visual name="visual">
        <geometry>
          <cylinder>
            <radius>0.03</radius>
            <length>0.06</length>
          </cylinder>
        </geometry>
        <material>
          <ambient>0.8 0.1 0.1 1</ambient>
          <diffuse>1.0 0.2 0.2 1</diffuse>
          <specular>0.8 0.8 0.8 1</specular>
        </material>
      </visual>
      <!-- 2D激光雷达传感器 -->
      <sensor name="laser" type="ray">
        <pose>0 0 0 0 0 0</pose>
        <update_rate>20</update_rate>
        <visualize>true</visualize>
        <ray>
          <scan>
            <horizontal>
              <samples>360</samples>
              <resolution>1</resolution>
              <min_angle>-3.14159</min_angle>
              <max_angle>3.14159</max_angle>
            </horizontal>
          </scan>
          <range>
            <min>0.1</min>
            <max>12.0</max>
            <resolution>0.01</resolution>
          </range>
          <noise>
            <type>gaussian</type>
            <mean>0.0</mean>
            <stddev>0.005</stddev>
          </noise>
        </ray>
        <plugin name="gazebo_ros_laser" filename="libgazebo_ros_ray_sensor.so">
          <ros>
            <namespace></namespace>
            <remapping>~/out:=scan_2d</remapping>
          </ros>
          <output_type>sensor_msgs/LaserScan</output_type>
          <frame_name>chassis</frame_name>
        </plugin>
      </sensor>
    </link>

    <!-- RGB-D相机链接 (类似D435i) -->
    <link name="camera_link">
      <pose>0.22 0 0.35 0 0 0</pose>
      <inertial>
        <mass>0.072</mass>
        <inertia>
          <ixx>0.000024</ixx>
          <iyy>0.000024</iyy>
          <izz>0.000024</izz>
          <ixy>0</ixy>
          <ixz>0</ixz>
          <iyz>0</iyz>
        </inertia>
      </inertial>
      <collision name="collision">
        <geometry>
          <box>
            <size>0.1 0.025 0.025</size>
          </box>
        </geometry>
      </collision>
      <visual name="visual">
        <geometry>
          <box>
            <size>0.1 0.025 0.025</size>
          </box>
        </geometry>
        <material>
          <ambient>0.1 0.1 0.1 1</ambient>
          <diffuse>0.2 0.2 0.2 1</diffuse>
          <specular>0.3 0.3 0.3 1</specular>
        </material>
      </visual>

      <!-- RGB相机传感器 -->
      <sensor name="rgb_camera" type="camera">
        <pose>0 0 0 0 0 0</pose>
        <update_rate>30</update_rate>
        <visualize>true</visualize>
        <camera>
          <horizontal_fov>1.047</horizontal_fov>
          <image>
            <width>640</width>
            <height>480</height>
            <format>R8G8B8</format>
          </image>
          <clip>
            <near>0.1</near>
            <far>10</far>
          </clip>
          <noise>
            <type>gaussian</type>
            <mean>0</mean>
            <stddev>0.007</stddev>
          </noise>
        </camera>
        <plugin name="gazebo_ros_camera" filename="libgazebo_ros_camera.so">
          <ros>
            <namespace></namespace>
            <remapping>~/image_raw:=camera/rgb/image_raw</remapping>
            <remapping>~/camera_info:=camera/rgb/camera_info</remapping>
          </ros>
          <camera_name>rgb_camera</camera_name>
          <frame_name>camera_link</frame_name>
          <hack_baseline>0.07</hack_baseline>
        </plugin>
      </sensor>

      <!-- 深度相机传感器 -->
      <sensor name="depth_camera" type="depth">
        <pose>0 0 0 0 0 0</pose>
        <update_rate>30</update_rate>
        <visualize>true</visualize>
        <camera>
          <horizontal_fov>1.047</horizontal_fov>
          <image>
            <width>640</width>
            <height>480</height>
            <format>R_FLOAT32</format>
          </image>
          <clip>
            <near>0.1</near>
            <far>10</far>
          </clip>
          <noise>
            <type>gaussian</type>
            <mean>0</mean>
            <stddev>0.01</stddev>
          </noise>
        </camera>
        <plugin name="gazebo_ros_depth_camera" filename="libgazebo_ros_camera.so">
          <ros>
            <namespace></namespace>
            <remapping>~/image_raw:=camera/depth/image_raw</remapping>
            <remapping>~/camera_info:=camera/depth/camera_info</remapping>
            <remapping>~/points:=camera/depth/points</remapping>
          </ros>
          <camera_name>depth_camera</camera_name>
          <frame_name>camera_link</frame_name>
          <hack_baseline>0.07</hack_baseline>
        </plugin>
      </sensor>
    </link>
    
    <joint type="revolute" name="left_wheel_hinge">
      <pose>0 0 -0.03 0 0 0</pose>
      <child>left_wheel</child>
      <parent>chassis</parent>
      <axis>
        <xyz>0 1 0</xyz>
        <use_parent_model_frame>true</use_parent_model_frame>
      </axis>
    </joint>
    
    <joint type="revolute" name="right_wheel_hinge">
      <pose>0 0 0.03 0 0 0</pose>
      <child>right_wheel</child>
      <parent>chassis</parent>
      <axis>
        <xyz>0 1 0</xyz>
        <use_parent_model_frame>true</use_parent_model_frame>
      </axis>
    </joint>

    <!-- 激光雷达关节 -->
    <joint name="lidar_joint" type="fixed">
      <child>lidar_link</child>
      <parent>chassis</parent>
    </joint>

    <!-- 2D激光雷达关节 -->
    <joint name="laser_joint" type="fixed">
      <child>laser_link</child>
      <parent>chassis</parent>
    </joint>

    <!-- RGB-D相机关节 -->
    <joint name="camera_joint" type="fixed">
      <child>camera_link</child>
      <parent>chassis</parent>
    </joint>
    
    <!-- 差速驱动插件 -->
    <plugin filename="libgazebo_ros_diff_drive.so" name="differential_drive_controller">
      <update_rate>50</update_rate>
      <left_joint>left_wheel_hinge</left_joint>
      <right_joint>right_wheel_hinge</right_joint>
      <wheel_separation>0.34</wheel_separation>
      <wheel_diameter>0.22</wheel_diameter>
      <max_wheel_torque>20</max_wheel_torque>
      <max_wheel_acceleration>1.0</max_wheel_acceleration>
      <command_topic>cmd_vel</command_topic>
      <publish_odom>true</publish_odom>
      <publish_odom_tf>true</publish_odom_tf>
      <publish_wheel_tf>true</publish_wheel_tf>
      <odometry_topic>odom</odometry_topic>
      <odometry_frame>odom</odometry_frame>
      <robot_base_frame>chassis</robot_base_frame>
    </plugin>
  </model>
</sdf> 